<?xml version="1.0"?>
<robot xmlns:xacro="http://ros.org/wiki/xacro">
  <xacro:macro name="arm_link" params="*parent *origin prefix">
    <link name="${prefix}_arm_link">
      <origin xyz="0 0 0" rpy="0 0 0"/>
      <visual>
        <geometry>
          <cylinder radius="0.05" length="0.02"/>
        </geometry>
        <material name="${prefix}_arm_material">
          <color rgba="0 0.4 0.5 1"/>
        </material>
      </visual>
      <collision>
        <geometry>
          <cylinder radius="0.05" length="0.02"/>
        </geometry>
      </collision>
      <inertial>
        <origin xyz="0 0 0" rpy="0 0 0"/>
        <mass value="0.1"/>
        <inertia ixx="0.0025" ixy="0" ixz="0" iyy="0.0025" iyz="0" izz="0.0025"/>
      </inertial>
    </link>
    <link name="${prefix}_lower_arm_link">
      <origin xyz="0 0 0" rpy="0 0 0"/>
      <visual>
        <origin xyz="0 0 0.15" rpy="0 0 0"/>
        <geometry>
          <cylinder radius="0.02" length="0.3"/>
        </geometry>
        <material name="${prefix}_arm_material"/>
      </visual>
      <collision>
        <origin xyz="0 0 0.15" rpy="0 0 0"/>
        <geometry>
          <cylinder radius="0.02" length="0.3"/>
        </geometry>
      </collision>
      <inertial>
        <origin xyz="0 0 0" rpy="0 0 0"/>
        <mass value="0.1"/>
        <inertia ixx="0.0025" ixy="0" ixz="0" iyy="0.0025" iyz="0" izz="0.0025"/>
      </inertial>
    </link>
    <link name="${prefix}_upper_arm_link">
      <origin xyz="0 0 0" rpy="0 0 0"/>
      <visual>
        <origin xyz="0 0 0.15" rpy="0 0 0"/>
        <geometry>
          <cylinder radius="0.02" length="0.3"/>
        </geometry>
        <material name="${prefix}_arm_material"/>
      </visual>
      <collision>
        <origin xyz="0 0 0.15" rpy="0 0 0"/>
        <geometry>
          <cylinder radius="0.02" length="0.3"/>
        </geometry>
      </collision>
      <inertial>
        <origin xyz="0 0 0" rpy="0 0 0"/>
        <mass value="0.1"/>
        <inertia ixx="0.0025" ixy="0" ixz="0" iyy="0.0025" iyz="0" izz="0.0025"/>
      </inertial>
    </link>
    <gazebo reference="${prefix}_arm_link">
      <self_collide>true</self_collide>
    </gazebo>
    <gazebo reference="${prefix}_lower_arm_link">
      <self_collide>true</self_collide>
    </gazebo>
    <gazebo reference="${prefix}_upper_arm_link">
      <self_collide>true</self_collide>
    </gazebo>
    <joint name="${prefix}_arm_joint" type="fixed">
      <xacro:insert_block name="parent"/>
      <child link="${prefix}_arm_link"/>
      <axis xyz="0 0 1"/>
      <xacro:insert_block name="origin"/>
    </joint>
    <joint name="${prefix}_lower_arm_joint" type="continuous">
      <parent link="${prefix}_arm_link"/>
      <child link="${prefix}_lower_arm_link"/>
      <axis xyz="0 1 0"/>
      <origin xyz="0 0 0" rpy="0 0 0"/>
      <limit effort="1.0" velocity="1.0"/>
      <dynamics damping="0.01" friction="0.001" lower="-1.57" upper="1.57"/>
    </joint>
    <joint name="${prefix}_upper_arm_joint" type="continuous">
      <parent link="${prefix}_lower_arm_link"/>
      <child link="${prefix}_upper_arm_link"/>
      <axis xyz="0 1 0"/>
      <origin xyz="0 0 0.3" rpy="0 0 0"/>
      <limit effort="1.0" velocity="1.0"/>
      <dynamics damping="0.01" friction="0.001" lower="-1.57" upper="1.57"/>
    </joint>
  </xacro:macro>
</robot>
