<?xml version="1.0"?>
<robot xmlns:xacro="http://ros.org/wiki/xacro">
  <xacro:macro name="swivel_caster" params="*parent *origin prefix">
    <link name="${prefix}_swivel_link">
      <origin xyz="0 0 0" rpy="0 0 0"/>
      <visual>
        <geometry>
          <cylinder radius="0.04" length="0.008"/>
        </geometry>
        <material name="${prefix}_swivel_material">
          <color rgba="0 0.2 0.5 1"/>
        </material>
      </visual>
      <collision>
        <geometry>
          <cylinder radius="0.04" length="0.008"/>
        </geometry>
      </collision>
      <inertial>
        <origin xyz="0 0 0" rpy="0 0 0"/>
        <mass value="0.05"/>
        <inertia ixx="0.0025" ixy="0" ixz="0" iyy="0.0025" iyz="0" izz="0.005"/>
      </inertial>
    </link>
    <link name="${prefix}_caster_link">
      <origin xyz="0 0 0" rpy="0 0 0"/>
      <visual>
        <geometry>
          <cylinder radius="0.04" length="0.02"/>
        </geometry>
        <material name="${prefix}_wheel_material">
          <color rgba="0 0.2 0.5 1"/>
        </material>
      </visual>
      <collision>
        <geometry>
          <cylinder radius="0.04" length="0.02"/>
        </geometry>
      </collision>
      <inertial>
        <origin xyz="0 0 0" rpy="0 0 0"/>
        <mass value="0.1"/>
        <inertia ixx="0.0025" ixy="0" ixz="0" iyy="0.0025" iyz="0" izz="0.005"/>
      </inertial>
    </link>
    <joint name="${prefix}_swivel_joint" type="continuous">
      <xacro:insert_block name="parent"/>
      <child link="${prefix}_swivel_link"/>
      <axis xyz="0 0 1"/>
      <xacro:insert_block name="origin"/>
      <origin xyz="-0.2 0 0" rpy="0 0 0"/>
      <limit effort="0" velocity="0"/>
      <dynamics damping="0.001" friction="0.0001"/>
    </joint>
    <joint name="${prefix}_caster_joint" type="continuous">
      <parent link="${prefix}_swivel_link"/>
      <child link="${prefix}_caster_link"/>
      <axis xyz="0 0 1"/>
      <origin xyz="-0.03 0 -0.04" rpy="1.52 0 0"/>
      <limit effort="0" velocity="0"/>
      <dynamics damping="0.001" friction="0.0001"/>
    </joint>
  </xacro:macro>
</robot>
